[2025-05-07T15:22:32.904-0300] {local_task_job_runner.py:123} INFO - ::group::Pre task execution logs
[2025-05-07T15:22:32.919-0300] {taskinstance.py:2614} INFO - Dependencies all met for dep_context=non-requeueable deps ti=<TaskInstance: anomaly_detection.validate_data scheduled__2023-01-18T00:00:00+00:00 [queued]>
[2025-05-07T15:22:32.928-0300] {taskinstance.py:2614} INFO - Dependencies all met for dep_context=requeueable deps ti=<TaskInstance: anomaly_detection.validate_data scheduled__2023-01-18T00:00:00+00:00 [queued]>
[2025-05-07T15:22:32.928-0300] {taskinstance.py:2867} INFO - Starting attempt 1 of 2
[2025-05-07T15:22:33.284-0300] {taskinstance.py:2890} INFO - Executing <Task(PythonOperator): validate_data> on 2023-01-18 00:00:00+00:00
[2025-05-07T15:22:33.315-0300] {logging_mixin.py:190} WARNING - /home/pyshell/airflow_env/lib/python3.12/site-packages/airflow/task/task_runner/standard_task_runner.py:70 DeprecationWarning: This process (pid=40285) is multi-threaded, use of fork() may lead to deadlocks in the child.
[2025-05-07T15:22:33.315-0300] {standard_task_runner.py:104} INFO - Running: ['airflow', 'tasks', 'run', 'anomaly_detection', 'validate_data', 'scheduled__2023-01-18T00:00:00+00:00', '--job-id', '197', '--raw', '--subdir', 'DAGS_FOLDER/anomaly_detection.py', '--cfg-path', '/tmp/tmpmanqaakv']
[2025-05-07T15:22:33.317-0300] {standard_task_runner.py:105} INFO - Job 197: Subtask validate_data
[2025-05-07T15:22:33.317-0300] {standard_task_runner.py:72} INFO - Started process 40304 to run task
[2025-05-07T15:22:33.904-0300] {task_command.py:467} INFO - Running <TaskInstance: anomaly_detection.validate_data scheduled__2023-01-18T00:00:00+00:00 [running]> on host pyshell
[2025-05-07T15:22:35.513-0300] {taskinstance.py:3134} INFO - Exporting env vars: AIRFLOW_CTX_DAG_OWNER='airflow' AIRFLOW_CTX_DAG_ID='anomaly_detection' AIRFLOW_CTX_TASK_ID='validate_data' AIRFLOW_CTX_EXECUTION_DATE='2023-01-18T00:00:00+00:00' AIRFLOW_CTX_TRY_NUMBER='1' AIRFLOW_CTX_DAG_RUN_ID='scheduled__2023-01-18T00:00:00+00:00'
[2025-05-07T15:22:35.515-0300] {taskinstance.py:732} INFO - ::endgroup::
[2025-05-07T15:22:35.622-0300] {python.py:240} INFO - Done. Returned value was: None
[2025-05-07T15:22:35.628-0300] {taskinstance.py:341} INFO - ::group::Post task execution logs
[2025-05-07T15:22:35.629-0300] {taskinstance.py:353} INFO - Marking task as SUCCESS. dag_id=anomaly_detection, task_id=validate_data, run_id=scheduled__2023-01-18T00:00:00+00:00, execution_date=20230118T000000, start_date=20250507T182232, end_date=20250507T182235
[2025-05-07T15:22:36.507-0300] {local_task_job_runner.py:266} INFO - Task exited with return code 0
[2025-05-07T15:22:36.562-0300] {taskinstance.py:3901} INFO - 1 downstream tasks scheduled from follow-on schedule check
[2025-05-07T15:22:37.105-0300] {local_task_job_runner.py:245} INFO - ::endgroup::
