[2025-05-07T15:36:57.183-0300] {local_task_job_runner.py:123} INFO - ::group::Pre task execution logs
[2025-05-07T15:36:57.191-0300] {taskinstance.py:2614} INFO - Dependencies all met for dep_context=non-requeueable deps ti=<TaskInstance: anomaly_detection.validate_data scheduled__2023-02-20T00:00:00+00:00 [queued]>
[2025-05-07T15:36:57.196-0300] {taskinstance.py:2614} INFO - Dependencies all met for dep_context=requeueable deps ti=<TaskInstance: anomaly_detection.validate_data scheduled__2023-02-20T00:00:00+00:00 [queued]>
[2025-05-07T15:36:57.196-0300] {taskinstance.py:2867} INFO - Starting attempt 1 of 2
[2025-05-07T15:36:57.500-0300] {taskinstance.py:2890} INFO - Executing <Task(PythonOperator): validate_data> on 2023-02-20 00:00:00+00:00
[2025-05-07T15:36:57.531-0300] {logging_mixin.py:190} WARNING - /home/pyshell/airflow_env/lib/python3.12/site-packages/airflow/task/task_runner/standard_task_runner.py:70 DeprecationWarning: This process (pid=42210) is multi-threaded, use of fork() may lead to deadlocks in the child.
[2025-05-07T15:36:57.531-0300] {standard_task_runner.py:104} INFO - Running: ['airflow', 'tasks', 'run', 'anomaly_detection', 'validate_data', 'scheduled__2023-02-20T00:00:00+00:00', '--job-id', '262', '--raw', '--subdir', 'DAGS_FOLDER/anomaly_detection.py', '--cfg-path', '/tmp/tmpm9zeooll']
[2025-05-07T15:36:57.533-0300] {standard_task_runner.py:105} INFO - Job 262: Subtask validate_data
[2025-05-07T15:36:57.533-0300] {standard_task_runner.py:72} INFO - Started process 42230 to run task
[2025-05-07T15:36:57.852-0300] {task_command.py:467} INFO - Running <TaskInstance: anomaly_detection.validate_data scheduled__2023-02-20T00:00:00+00:00 [running]> on host pyshell
[2025-05-07T15:36:58.551-0300] {taskinstance.py:3134} INFO - Exporting env vars: AIRFLOW_CTX_DAG_OWNER='airflow' AIRFLOW_CTX_DAG_ID='anomaly_detection' AIRFLOW_CTX_TASK_ID='validate_data' AIRFLOW_CTX_EXECUTION_DATE='2023-02-20T00:00:00+00:00' AIRFLOW_CTX_TRY_NUMBER='1' AIRFLOW_CTX_DAG_RUN_ID='scheduled__2023-02-20T00:00:00+00:00'
[2025-05-07T15:36:58.554-0300] {taskinstance.py:732} INFO - ::endgroup::
[2025-05-07T15:36:58.624-0300] {python.py:240} INFO - Done. Returned value was: None
[2025-05-07T15:36:58.859-0300] {taskinstance.py:341} INFO - ::group::Post task execution logs
[2025-05-07T15:36:58.860-0300] {taskinstance.py:353} INFO - Marking task as SUCCESS. dag_id=anomaly_detection, task_id=validate_data, run_id=scheduled__2023-02-20T00:00:00+00:00, execution_date=20230220T000000, start_date=20250507T183657, end_date=20250507T183658
[2025-05-07T15:36:59.516-0300] {local_task_job_runner.py:266} INFO - Task exited with return code 0
[2025-05-07T15:37:00.538-0300] {taskinstance.py:3901} INFO - 1 downstream tasks scheduled from follow-on schedule check
[2025-05-07T15:37:00.844-0300] {local_task_job_runner.py:245} INFO - ::endgroup::
