[2025-05-07T15:36:43.276-0300] {local_task_job_runner.py:123} INFO - ::group::Pre task execution logs
[2025-05-07T15:36:43.286-0300] {taskinstance.py:2614} INFO - Dependencies all met for dep_context=non-requeueable deps ti=<TaskInstance: anomaly_detection.validate_data scheduled__2023-02-19T00:00:00+00:00 [queued]>
[2025-05-07T15:36:43.292-0300] {taskinstance.py:2614} INFO - Dependencies all met for dep_context=requeueable deps ti=<TaskInstance: anomaly_detection.validate_data scheduled__2023-02-19T00:00:00+00:00 [queued]>
[2025-05-07T15:36:43.292-0300] {taskinstance.py:2867} INFO - Starting attempt 1 of 2
[2025-05-07T15:36:43.570-0300] {taskinstance.py:2890} INFO - Executing <Task(PythonOperator): validate_data> on 2023-02-19 00:00:00+00:00
[2025-05-07T15:36:43.603-0300] {logging_mixin.py:190} WARNING - /home/pyshell/airflow_env/lib/python3.12/site-packages/airflow/task/task_runner/standard_task_runner.py:70 DeprecationWarning: This process (pid=42179) is multi-threaded, use of fork() may lead to deadlocks in the child.
[2025-05-07T15:36:43.604-0300] {standard_task_runner.py:72} INFO - Started process 42198 to run task
[2025-05-07T15:36:43.603-0300] {standard_task_runner.py:104} INFO - Running: ['airflow', 'tasks', 'run', 'anomaly_detection', 'validate_data', 'scheduled__2023-02-19T00:00:00+00:00', '--job-id', '261', '--raw', '--subdir', 'DAGS_FOLDER/anomaly_detection.py', '--cfg-path', '/tmp/tmpzymi5oo7']
[2025-05-07T15:36:43.605-0300] {standard_task_runner.py:105} INFO - Job 261: Subtask validate_data
[2025-05-07T15:36:43.950-0300] {task_command.py:467} INFO - Running <TaskInstance: anomaly_detection.validate_data scheduled__2023-02-19T00:00:00+00:00 [running]> on host pyshell
[2025-05-07T15:36:44.603-0300] {taskinstance.py:3134} INFO - Exporting env vars: AIRFLOW_CTX_DAG_OWNER='airflow' AIRFLOW_CTX_DAG_ID='anomaly_detection' AIRFLOW_CTX_TASK_ID='validate_data' AIRFLOW_CTX_EXECUTION_DATE='2023-02-19T00:00:00+00:00' AIRFLOW_CTX_TRY_NUMBER='1' AIRFLOW_CTX_DAG_RUN_ID='scheduled__2023-02-19T00:00:00+00:00'
[2025-05-07T15:36:44.605-0300] {taskinstance.py:732} INFO - ::endgroup::
[2025-05-07T15:36:44.673-0300] {python.py:240} INFO - Done. Returned value was: None
[2025-05-07T15:36:44.678-0300] {taskinstance.py:341} INFO - ::group::Post task execution logs
[2025-05-07T15:36:44.679-0300] {taskinstance.py:353} INFO - Marking task as SUCCESS. dag_id=anomaly_detection, task_id=validate_data, run_id=scheduled__2023-02-19T00:00:00+00:00, execution_date=20230219T000000, start_date=20250507T183643, end_date=20250507T183644
[2025-05-07T15:36:45.389-0300] {local_task_job_runner.py:266} INFO - Task exited with return code 0
[2025-05-07T15:36:45.412-0300] {taskinstance.py:3901} INFO - 1 downstream tasks scheduled from follow-on schedule check
[2025-05-07T15:36:45.697-0300] {local_task_job_runner.py:245} INFO - ::endgroup::
