[2025-05-07T15:50:44.589-0300] {local_task_job_runner.py:123} INFO - ::group::Pre task execution logs
[2025-05-07T15:50:44.600-0300] {taskinstance.py:2614} INFO - Dependencies all met for dep_context=non-requeueable deps ti=<TaskInstance: anomaly_detection.validate_data scheduled__2023-03-23T00:00:00+00:00 [queued]>
[2025-05-07T15:50:44.606-0300] {taskinstance.py:2614} INFO - Dependencies all met for dep_context=requeueable deps ti=<TaskInstance: anomaly_detection.validate_data scheduled__2023-03-23T00:00:00+00:00 [queued]>
[2025-05-07T15:50:44.607-0300] {taskinstance.py:2867} INFO - Starting attempt 1 of 2
[2025-05-07T15:50:44.900-0300] {taskinstance.py:2890} INFO - Executing <Task(PythonOperator): validate_data> on 2023-03-23 00:00:00+00:00
[2025-05-07T15:50:44.934-0300] {logging_mixin.py:190} WARNING - /home/pyshell/airflow_env/lib/python3.12/site-packages/airflow/task/task_runner/standard_task_runner.py:70 DeprecationWarning: This process (pid=44070) is multi-threaded, use of fork() may lead to deadlocks in the child.
[2025-05-07T15:50:44.934-0300] {standard_task_runner.py:104} INFO - Running: ['airflow', 'tasks', 'run', 'anomaly_detection', 'validate_data', 'scheduled__2023-03-23T00:00:00+00:00', '--job-id', '325', '--raw', '--subdir', 'DAGS_FOLDER/anomaly_detection.py', '--cfg-path', '/tmp/tmph7279zvg']
[2025-05-07T15:50:44.935-0300] {standard_task_runner.py:105} INFO - Job 325: Subtask validate_data
[2025-05-07T15:50:44.935-0300] {standard_task_runner.py:72} INFO - Started process 44089 to run task
[2025-05-07T15:50:45.274-0300] {task_command.py:467} INFO - Running <TaskInstance: anomaly_detection.validate_data scheduled__2023-03-23T00:00:00+00:00 [running]> on host pyshell
[2025-05-07T15:50:47.476-0300] {taskinstance.py:3134} INFO - Exporting env vars: AIRFLOW_CTX_DAG_OWNER='airflow' AIRFLOW_CTX_DAG_ID='anomaly_detection' AIRFLOW_CTX_TASK_ID='validate_data' AIRFLOW_CTX_EXECUTION_DATE='2023-03-23T00:00:00+00:00' AIRFLOW_CTX_TRY_NUMBER='1' AIRFLOW_CTX_DAG_RUN_ID='scheduled__2023-03-23T00:00:00+00:00'
[2025-05-07T15:50:47.478-0300] {taskinstance.py:732} INFO - ::endgroup::
[2025-05-07T15:50:47.616-0300] {python.py:240} INFO - Done. Returned value was: None
[2025-05-07T15:50:47.810-0300] {taskinstance.py:341} INFO - ::group::Post task execution logs
[2025-05-07T15:50:47.811-0300] {taskinstance.py:353} INFO - Marking task as SUCCESS. dag_id=anomaly_detection, task_id=validate_data, run_id=scheduled__2023-03-23T00:00:00+00:00, execution_date=20230323T000000, start_date=20250507T185044, end_date=20250507T185047
[2025-05-07T15:50:48.969-0300] {local_task_job_runner.py:266} INFO - Task exited with return code 0
[2025-05-07T15:50:49.021-0300] {taskinstance.py:3901} INFO - 1 downstream tasks scheduled from follow-on schedule check
[2025-05-07T15:50:49.523-0300] {local_task_job_runner.py:245} INFO - ::endgroup::
[2025-05-07T15:50:49.939-0300] {standard_task_runner.py:217} INFO - Process not found (most likely exited), stop collecting metrics
