[2025-05-07T15:39:44.585-0300] {local_task_job_runner.py:123} INFO - ::group::Pre task execution logs
[2025-05-07T15:39:44.600-0300] {taskinstance.py:2614} INFO - Dependencies all met for dep_context=non-requeueable deps ti=<TaskInstance: anomaly_detection.validate_data scheduled__2023-02-26T00:00:00+00:00 [queued]>
[2025-05-07T15:39:44.609-0300] {taskinstance.py:2614} INFO - Dependencies all met for dep_context=requeueable deps ti=<TaskInstance: anomaly_detection.validate_data scheduled__2023-02-26T00:00:00+00:00 [queued]>
[2025-05-07T15:39:44.609-0300] {taskinstance.py:2867} INFO - Starting attempt 1 of 2
[2025-05-07T15:39:44.953-0300] {taskinstance.py:2890} INFO - Executing <Task(PythonOperator): validate_data> on 2023-02-26 00:00:00+00:00
[2025-05-07T15:39:44.985-0300] {logging_mixin.py:190} WARNING - /home/pyshell/airflow_env/lib/python3.12/site-packages/airflow/task/task_runner/standard_task_runner.py:70 DeprecationWarning: This process (pid=42573) is multi-threaded, use of fork() may lead to deadlocks in the child.
[2025-05-07T15:39:44.985-0300] {standard_task_runner.py:104} INFO - Running: ['airflow', 'tasks', 'run', 'anomaly_detection', 'validate_data', 'scheduled__2023-02-26T00:00:00+00:00', '--job-id', '275', '--raw', '--subdir', 'DAGS_FOLDER/anomaly_detection.py', '--cfg-path', '/tmp/tmpw48xe3_u']
[2025-05-07T15:39:44.986-0300] {standard_task_runner.py:105} INFO - Job 275: Subtask validate_data
[2025-05-07T15:39:44.986-0300] {standard_task_runner.py:72} INFO - Started process 42592 to run task
[2025-05-07T15:39:45.361-0300] {task_command.py:467} INFO - Running <TaskInstance: anomaly_detection.validate_data scheduled__2023-02-26T00:00:00+00:00 [running]> on host pyshell
[2025-05-07T15:39:46.823-0300] {taskinstance.py:3134} INFO - Exporting env vars: AIRFLOW_CTX_DAG_OWNER='airflow' AIRFLOW_CTX_DAG_ID='anomaly_detection' AIRFLOW_CTX_TASK_ID='validate_data' AIRFLOW_CTX_EXECUTION_DATE='2023-02-26T00:00:00+00:00' AIRFLOW_CTX_TRY_NUMBER='1' AIRFLOW_CTX_DAG_RUN_ID='scheduled__2023-02-26T00:00:00+00:00'
[2025-05-07T15:39:46.826-0300] {taskinstance.py:732} INFO - ::endgroup::
[2025-05-07T15:39:46.929-0300] {python.py:240} INFO - Done. Returned value was: None
[2025-05-07T15:39:47.172-0300] {taskinstance.py:341} INFO - ::group::Post task execution logs
[2025-05-07T15:39:47.173-0300] {taskinstance.py:353} INFO - Marking task as SUCCESS. dag_id=anomaly_detection, task_id=validate_data, run_id=scheduled__2023-02-26T00:00:00+00:00, execution_date=20230226T000000, start_date=20250507T183944, end_date=20250507T183947
[2025-05-07T15:39:48.013-0300] {local_task_job_runner.py:266} INFO - Task exited with return code 0
[2025-05-07T15:39:48.043-0300] {taskinstance.py:3901} INFO - 1 downstream tasks scheduled from follow-on schedule check
[2025-05-07T15:39:48.453-0300] {local_task_job_runner.py:245} INFO - ::endgroup::
