[2025-05-07T15:47:50.292-0300] {local_task_job_runner.py:123} INFO - ::group::Pre task execution logs
[2025-05-07T15:47:50.301-0300] {taskinstance.py:2614} INFO - Dependencies all met for dep_context=non-requeueable deps ti=<TaskInstance: anomaly_detection.validate_data scheduled__2023-03-17T00:00:00+00:00 [queued]>
[2025-05-07T15:47:50.307-0300] {taskinstance.py:2614} INFO - Dependencies all met for dep_context=requeueable deps ti=<TaskInstance: anomaly_detection.validate_data scheduled__2023-03-17T00:00:00+00:00 [queued]>
[2025-05-07T15:47:50.307-0300] {taskinstance.py:2867} INFO - Starting attempt 1 of 2
[2025-05-07T15:47:50.622-0300] {taskinstance.py:2890} INFO - Executing <Task(PythonOperator): validate_data> on 2023-03-17 00:00:00+00:00
[2025-05-07T15:47:50.652-0300] {logging_mixin.py:190} WARNING - /home/pyshell/airflow_env/lib/python3.12/site-packages/airflow/task/task_runner/standard_task_runner.py:70 DeprecationWarning: This process (pid=43674) is multi-threaded, use of fork() may lead to deadlocks in the child.
[2025-05-07T15:47:50.652-0300] {standard_task_runner.py:104} INFO - Running: ['airflow', 'tasks', 'run', 'anomaly_detection', 'validate_data', 'scheduled__2023-03-17T00:00:00+00:00', '--job-id', '312', '--raw', '--subdir', 'DAGS_FOLDER/anomaly_detection.py', '--cfg-path', '/tmp/tmpe2zktbd8']
[2025-05-07T15:47:50.653-0300] {standard_task_runner.py:105} INFO - Job 312: Subtask validate_data
[2025-05-07T15:47:50.653-0300] {standard_task_runner.py:72} INFO - Started process 43692 to run task
[2025-05-07T15:47:51.001-0300] {task_command.py:467} INFO - Running <TaskInstance: anomaly_detection.validate_data scheduled__2023-03-17T00:00:00+00:00 [running]> on host pyshell
[2025-05-07T15:47:51.813-0300] {taskinstance.py:3134} INFO - Exporting env vars: AIRFLOW_CTX_DAG_OWNER='airflow' AIRFLOW_CTX_DAG_ID='anomaly_detection' AIRFLOW_CTX_TASK_ID='validate_data' AIRFLOW_CTX_EXECUTION_DATE='2023-03-17T00:00:00+00:00' AIRFLOW_CTX_TRY_NUMBER='1' AIRFLOW_CTX_DAG_RUN_ID='scheduled__2023-03-17T00:00:00+00:00'
[2025-05-07T15:47:51.815-0300] {taskinstance.py:732} INFO - ::endgroup::
[2025-05-07T15:47:51.940-0300] {python.py:240} INFO - Done. Returned value was: None
[2025-05-07T15:47:53.184-0300] {taskinstance.py:341} INFO - ::group::Post task execution logs
[2025-05-07T15:47:53.185-0300] {taskinstance.py:353} INFO - Marking task as SUCCESS. dag_id=anomaly_detection, task_id=validate_data, run_id=scheduled__2023-03-17T00:00:00+00:00, execution_date=20230317T000000, start_date=20250507T184750, end_date=20250507T184753
[2025-05-07T15:47:53.882-0300] {local_task_job_runner.py:266} INFO - Task exited with return code 0
[2025-05-07T15:47:53.928-0300] {taskinstance.py:3901} INFO - 1 downstream tasks scheduled from follow-on schedule check
[2025-05-07T15:47:54.279-0300] {local_task_job_runner.py:245} INFO - ::endgroup::
